# 错误、调试和测试

------

[TOC]



## 1.错误处理

在程序运行的过程中，如果发生了错误，可以事先约定返回一个错误代码，这样，就可以知道是否有错，以及出错的原因。在操作系统提供的调用中，返回错误码非常常见。比如打开文件的函数`open()`，成功时返回文件描述符（就是一个整数），出错时返回`-1`。

用错误码来表示是否出错十分不便，因为函数本身应该返回的正常结果和错误码混在一起，造成调用者必须用大量的代码来判断是否出错：

```python
def foo():
    r = some_function()
    if r==(-1):
        return (-1)
    # do something
    return r

def bar():
    r = foo()
    if r==(-1):
        print('Error')
    else:
        pass
```

一旦出错，还要一级一级上报，直到某个函数可以处理该错误（比如，给用户输出一个错误信息）。高级语言通常都内置了一套`try...except...finally...`的错误处理机制，Python也不例外

### 1.1 try

让我们用一个例子来看看`try`的机制：

```python
try:
    print('try...')
    r = 10 / 0
    print('result:', r)
except ZeroDivisionError as e:
    print('except:', e)
finally:
    print('finally...')
print('END')
```

当我们认为某些代码可能会出错时，就可以用`try`来运行这段代码，如果执行出错，则后续代码不会继续执行，而是直接跳转至错误处理代码，即`except`语句块，执行完`except`后，如果有`finally`语句块，则执行`finally`语句块，至此，执行完毕。

### 1.2调用栈

如果错误没有被捕获，它就会一直往上抛，最后被Python解释器捕获，打印一个错误信息，然后程序退出。来看看`err.py`：

```python
# err.py:
def foo(s):
    return 10 / int(s)

def bar(s):
    return foo(s) * 2

def main():
    bar('0')

main()

'''
执行结果

$ python3 err.py
Traceback (most recent call last):
  File "err.py", line 11, in <module>
    main()
  File "err.py", line 9, in main
    bar('0')
  File "err.py", line 6, in bar
    return foo(s) * 2
  File "err.py", line 3, in foo
    return 10 / int(s)
ZeroDivisionError: division by zero

出错并不可怕，可怕的是不知道哪里出错了。解读错误信息是定位错误的关键。我们从上往下可以看到整个错误的调用函数链：

错误信息解析
err.py  中 11 行出错 在 main() 函数中
因为  9 行  bar("0") 出错
因为  6 行  foo(s) * 2 出错
因为  3 行  return 10 / int(s) 出错
出错原因 0 被做分母
'''
```

### 1.3记录错误

如果不捕获错误，自然可以让Python解释器来打印出错误堆栈，但程序也被结束了。既然我们能捕获错误，就可以把错误堆栈打印出来，然后分析错误原因，同时，让程序继续执行下去。Python内置的`logging`模块可以非常容易地记录错误信息：

```python
# err_logging.py

import logging

def foo(s):
    return 10 / int(s)

def bar(s):
    return foo(s) * 2

def main():
    try:
        bar('0')
    except Exception as e:
        logging.exception(e)

main()
print('END')



'''
$ python3 err_logging.py
ERROR:root:division by zero
Traceback (most recent call last):
  File "err_logging.py", line 13, in main
    bar('0')
  File "err_logging.py", line 9, in bar
    return foo(s) * 2
  File "err_logging.py", line 6, in foo
    return 10 / int(s)
ZeroDivisionError: division by zero
END
'''
```

### 1.4抛出错误

因为错误是class，捕获一个错误就是捕获到该class的一个实例。因此，错误并不是凭空产生的，而是有意创建并抛出的。Python的内置函数会抛出很多类型的错误，我们自己编写的函数也可以抛出错误。如果要抛出错误，首先根据需要，可以定义一个错误的class，选择好继承关系，然后，用`raise`语句抛出一个错误的实例：

```python

# err_raise.py
class FooError(ValueError):
    pass

def foo(s):
    n = int(s)
    if n==0:
        raise FooError('invalid value: %s' % s)
    return 10 / n

foo('0')
# 执行，可以最后跟踪到我们自己定义的错误：

'''
$ python3 err_raise.py 
Traceback (most recent call last):
  File "err_throw.py", line 11, in <module>
    foo('0')
  File "err_throw.py", line 8, in foo
    raise FooError('invalid value: %s' % s)
__main__.FooError: invalid value: 0
'''
```

只有在必要的时候才定义我们自己的错误类型。如果可以选择Python已有的内置的错误类型（比如`ValueError`，`TypeError`），尽量使用Python内置的错误类型。

另一种错误处理的方式：

```python
# err_reraise.py

def foo(s):
    n = int(s)
    if n==0:
        raise ValueError('invalid value: %s' % s)
    return 10 / n

def bar():
    try:
        foo('0')
    except ValueError as e:
        print('ValueError!')
        raise

bar()
```

其实这种错误处理方式不但没病，而且相当常见。捕获错误目的只是记录一下，便于后续追踪。但是，由于当前函数不知道应该怎么处理该错误，所以，最恰当的方式是继续往上抛，让顶层调用者去处理。好比一个员工处理不了一个问题时，就把问题抛给他的老板，如果他的老板也处理不了，就一直往上抛，最终会抛给CEO去处理。

## 2.调试

程序能一次写完并正常运行的概率很小，基本不超过1%。总会有各种各样的bug需要修正。有的bug很简单，看看错误信息就知道，有的bug很复杂，我们需要知道出错时，哪些变量的值是正确的，哪些变量的值是错误的，因此，需要一整套调试程序的手段来修复bug。

**法一** ： 直接  print 可能出问题的变量

**法二** :   断言

```python
# 凡是使用 print 的地方就可以 使用断言（assert）
def foo(s):
    n = int(s)
    assert n != 0, 'n is zero!' #如果断言失败，assert语句本身就会抛出AssertionError：
    return 10 / n

def main():
    foo('0')
```

程序中如果到处充斥着`assert`，和`print()`相比也好不到哪去。不过，启动Python解释器时可以用`-O`参数来关闭`assert`：

```python
$ python -O err.py
```

**法三** ： logging

把`print()`替换为`logging`是第3种方式，和`assert`比，`logging`不会抛出错误，而且可以输出到文件

用的时候可以再看



### **法四** : debug

**多数IDE  都集成了这些方法 ， 方便我们调试 。 也是最常用的调试方式**

## 3.单元测试与文档测试 用的时候看，基本不用